[2025-02-21T00:00:01.944+0000] {taskinstance.py:1103} INFO - Dependencies all met for dep_context=non-requeueable deps ti=<TaskInstance: data_quality_pipeline.check_quality_success_flag scheduled__2025-02-20T00:00:00+00:00 [queued]>
[2025-02-21T00:00:01.952+0000] {taskinstance.py:1103} INFO - Dependencies all met for dep_context=requeueable deps ti=<TaskInstance: data_quality_pipeline.check_quality_success_flag scheduled__2025-02-20T00:00:00+00:00 [queued]>
[2025-02-21T00:00:01.953+0000] {taskinstance.py:1308} INFO - Starting attempt 1 of 1
[2025-02-21T00:00:01.966+0000] {taskinstance.py:1327} INFO - Executing <Task(BranchPythonOperator): check_quality_success_flag> on 2025-02-20 00:00:00+00:00
[2025-02-21T00:00:01.975+0000] {standard_task_runner.py:57} INFO - Started process 16536 to run task
[2025-02-21T00:00:01.982+0000] {standard_task_runner.py:84} INFO - Running: ['***', 'tasks', 'run', 'data_quality_pipeline', 'check_quality_success_flag', 'scheduled__2025-02-20T00:00:00+00:00', '--job-id', '122', '--raw', '--subdir', 'DAGS_FOLDER/data_quality_pipeline.py', '--cfg-path', '/tmp/tmpchq8nhsb']
[2025-02-21T00:00:01.990+0000] {standard_task_runner.py:85} INFO - Job 122: Subtask check_quality_success_flag
[2025-02-21T00:00:02.046+0000] {task_command.py:410} INFO - Running <TaskInstance: data_quality_pipeline.check_quality_success_flag scheduled__2025-02-20T00:00:00+00:00 [running]> on host 29612c003465
[2025-02-21T00:00:02.111+0000] {taskinstance.py:1547} INFO - Exporting env vars: AIRFLOW_CTX_DAG_OWNER='***' AIRFLOW_CTX_DAG_ID='data_quality_pipeline' AIRFLOW_CTX_TASK_ID='check_quality_success_flag' AIRFLOW_CTX_EXECUTION_DATE='2025-02-20T00:00:00+00:00' AIRFLOW_CTX_TRY_NUMBER='1' AIRFLOW_CTX_DAG_RUN_ID='scheduled__2025-02-20T00:00:00+00:00'
[2025-02-21T00:00:02.112+0000] {python.py:183} INFO - Done. Returned value was: validate_data
[2025-02-21T00:00:02.113+0000] {python.py:216} INFO - Branch callable return validate_data
[2025-02-21T00:00:02.113+0000] {skipmixin.py:164} INFO - Following branch validate_data
[2025-02-21T00:00:02.119+0000] {taskinstance.py:1824} ERROR - Task failed with exception
Traceback (most recent call last):
  File "/home/airflow/.local/lib/python3.7/site-packages/airflow/operators/python.py", line 217, in execute
    self.skip_all_except(context["ti"], branch)
  File "/home/airflow/.local/lib/python3.7/site-packages/airflow/models/skipmixin.py", line 199, in skip_all_except
    "'branch_task_ids' must contain only valid task_ids. "
airflow.exceptions.AirflowException: 'branch_task_ids' must contain only valid task_ids. Invalid tasks found: {'validate_data'}.
[2025-02-21T00:00:02.123+0000] {taskinstance.py:1350} INFO - Marking task as FAILED. dag_id=data_quality_pipeline, task_id=check_quality_success_flag, execution_date=20250220T000000, start_date=20250221T000001, end_date=20250221T000002
[2025-02-21T00:00:02.131+0000] {standard_task_runner.py:109} ERROR - Failed to execute job 122 for task check_quality_success_flag ('branch_task_ids' must contain only valid task_ids. Invalid tasks found: {'validate_data'}.; 16536)
[2025-02-21T00:00:02.154+0000] {local_task_job_runner.py:225} INFO - Task exited with return code 1
[2025-02-21T00:00:02.177+0000] {taskinstance.py:2653} INFO - 0 downstream tasks scheduled from follow-on schedule check
