[2025-02-01T20:19:30.865+0000] {taskinstance.py:1103} INFO - Dependencies all met for dep_context=non-requeueable deps ti=<TaskInstance: ingestion_pipeline.generate_ingestion_data manual__2025-02-01T20:19:27.440925+00:00 [queued]>
[2025-02-01T20:19:30.874+0000] {taskinstance.py:1103} INFO - Dependencies all met for dep_context=requeueable deps ti=<TaskInstance: ingestion_pipeline.generate_ingestion_data manual__2025-02-01T20:19:27.440925+00:00 [queued]>
[2025-02-01T20:19:30.874+0000] {taskinstance.py:1308} INFO - Starting attempt 1 of 1
[2025-02-01T20:19:30.883+0000] {taskinstance.py:1327} INFO - Executing <Task(PythonOperator): generate_ingestion_data> on 2025-02-01 20:19:27.440925+00:00
[2025-02-01T20:19:30.887+0000] {standard_task_runner.py:57} INFO - Started process 244 to run task
[2025-02-01T20:19:30.889+0000] {standard_task_runner.py:84} INFO - Running: ['***', 'tasks', 'run', 'ingestion_pipeline', 'generate_ingestion_data', 'manual__2025-02-01T20:19:27.440925+00:00', '--job-id', '7', '--raw', '--subdir', 'DAGS_FOLDER/upstreams_data_ingestion_pipeline.py', '--cfg-path', '/tmp/tmp3_kdc73t']
[2025-02-01T20:19:30.891+0000] {standard_task_runner.py:85} INFO - Job 7: Subtask generate_ingestion_data
[2025-02-01T20:19:30.922+0000] {task_command.py:410} INFO - Running <TaskInstance: ingestion_pipeline.generate_ingestion_data manual__2025-02-01T20:19:27.440925+00:00 [running]> on host 7a8470bceba1
[2025-02-01T20:19:30.972+0000] {taskinstance.py:1547} INFO - Exporting env vars: AIRFLOW_CTX_DAG_OWNER='***' AIRFLOW_CTX_DAG_ID='ingestion_pipeline' AIRFLOW_CTX_TASK_ID='generate_ingestion_data' AIRFLOW_CTX_EXECUTION_DATE='2025-02-01T20:19:27.440925+00:00' AIRFLOW_CTX_TRY_NUMBER='1' AIRFLOW_CTX_DAG_RUN_ID='manual__2025-02-01T20:19:27.440925+00:00'
[2025-02-01T20:19:31.087+0000] {taskinstance.py:1824} ERROR - Task failed with exception
Traceback (most recent call last):
  File "/home/airflow/.local/lib/python3.7/site-packages/airflow/operators/python.py", line 181, in execute
    return_value = self.execute_callable()
  File "/home/airflow/.local/lib/python3.7/site-packages/airflow/operators/python.py", line 198, in execute_callable
    return self.python_callable(*self.op_args, **self.op_kwargs)
  File "/opt/airflow/dags/upstreams_curation.py", line 24, in generate_ingestion_data
    .config("spark.sql.shuffle.partitions", "8") \
  File "/home/airflow/.local/lib/python3.7/site-packages/pyspark/sql/session.py", line 269, in getOrCreate
    sc = SparkContext.getOrCreate(sparkConf)
  File "/home/airflow/.local/lib/python3.7/site-packages/pyspark/context.py", line 483, in getOrCreate
    SparkContext(conf=conf or SparkConf())
  File "/home/airflow/.local/lib/python3.7/site-packages/pyspark/context.py", line 195, in __init__
    SparkContext._ensure_initialized(self, gateway=gateway, conf=conf)
  File "/home/airflow/.local/lib/python3.7/site-packages/pyspark/context.py", line 417, in _ensure_initialized
    SparkContext._gateway = gateway or launch_gateway(conf)
  File "/home/airflow/.local/lib/python3.7/site-packages/pyspark/java_gateway.py", line 106, in launch_gateway
    raise RuntimeError("Java gateway process exited before sending its port number")
RuntimeError: Java gateway process exited before sending its port number
[2025-02-01T20:19:31.097+0000] {taskinstance.py:1350} INFO - Marking task as FAILED. dag_id=ingestion_pipeline, task_id=generate_ingestion_data, execution_date=20250201T201927, start_date=20250201T201930, end_date=20250201T201931
[2025-02-01T20:19:31.107+0000] {standard_task_runner.py:109} ERROR - Failed to execute job 7 for task generate_ingestion_data (Java gateway process exited before sending its port number; 244)
[2025-02-01T20:19:31.150+0000] {local_task_job_runner.py:225} INFO - Task exited with return code 1
[2025-02-01T20:19:31.169+0000] {taskinstance.py:2653} INFO - 0 downstream tasks scheduled from follow-on schedule check
