[2025-02-01T20:14:33.311+0000] {taskinstance.py:1103} INFO - Dependencies all met for dep_context=non-requeueable deps ti=<TaskInstance: ingestion_pipeline.generate_ingestion_data scheduled__2025-01-31T00:00:00+00:00 [queued]>
[2025-02-01T20:14:33.317+0000] {taskinstance.py:1103} INFO - Dependencies all met for dep_context=requeueable deps ti=<TaskInstance: ingestion_pipeline.generate_ingestion_data scheduled__2025-01-31T00:00:00+00:00 [queued]>
[2025-02-01T20:14:33.317+0000] {taskinstance.py:1308} INFO - Starting attempt 1 of 1
[2025-02-01T20:14:33.325+0000] {taskinstance.py:1327} INFO - Executing <Task(PythonOperator): generate_ingestion_data> on 2025-01-31 00:00:00+00:00
[2025-02-01T20:14:33.328+0000] {standard_task_runner.py:57} INFO - Started process 468 to run task
[2025-02-01T20:14:33.330+0000] {standard_task_runner.py:84} INFO - Running: ['***', 'tasks', 'run', 'ingestion_pipeline', 'generate_ingestion_data', 'scheduled__2025-01-31T00:00:00+00:00', '--job-id', '4', '--raw', '--subdir', 'DAGS_FOLDER/upstreams_data_ingestion_pipeline.py', '--cfg-path', '/tmp/tmpr6i752bb']
[2025-02-01T20:14:33.332+0000] {standard_task_runner.py:85} INFO - Job 4: Subtask generate_ingestion_data
[2025-02-01T20:14:33.361+0000] {task_command.py:410} INFO - Running <TaskInstance: ingestion_pipeline.generate_ingestion_data scheduled__2025-01-31T00:00:00+00:00 [running]> on host 8a41ec6729bc
[2025-02-01T20:14:33.407+0000] {taskinstance.py:1547} INFO - Exporting env vars: AIRFLOW_CTX_DAG_OWNER='***' AIRFLOW_CTX_DAG_ID='ingestion_pipeline' AIRFLOW_CTX_TASK_ID='generate_ingestion_data' AIRFLOW_CTX_EXECUTION_DATE='2025-01-31T00:00:00+00:00' AIRFLOW_CTX_TRY_NUMBER='1' AIRFLOW_CTX_DAG_RUN_ID='scheduled__2025-01-31T00:00:00+00:00'
[2025-02-01T20:14:33.523+0000] {taskinstance.py:1824} ERROR - Task failed with exception
Traceback (most recent call last):
  File "/home/airflow/.local/lib/python3.7/site-packages/airflow/operators/python.py", line 181, in execute
    return_value = self.execute_callable()
  File "/home/airflow/.local/lib/python3.7/site-packages/airflow/operators/python.py", line 198, in execute_callable
    return self.python_callable(*self.op_args, **self.op_kwargs)
  File "/opt/airflow/dags/upstreams_curation.py", line 24, in generate_ingestion_data
    .config("spark.sql.shuffle.partitions", "8") \
  File "/home/airflow/.local/lib/python3.7/site-packages/pyspark/sql/session.py", line 269, in getOrCreate
    sc = SparkContext.getOrCreate(sparkConf)
  File "/home/airflow/.local/lib/python3.7/site-packages/pyspark/context.py", line 483, in getOrCreate
    SparkContext(conf=conf or SparkConf())
  File "/home/airflow/.local/lib/python3.7/site-packages/pyspark/context.py", line 195, in __init__
    SparkContext._ensure_initialized(self, gateway=gateway, conf=conf)
  File "/home/airflow/.local/lib/python3.7/site-packages/pyspark/context.py", line 417, in _ensure_initialized
    SparkContext._gateway = gateway or launch_gateway(conf)
  File "/home/airflow/.local/lib/python3.7/site-packages/pyspark/java_gateway.py", line 106, in launch_gateway
    raise RuntimeError("Java gateway process exited before sending its port number")
RuntimeError: Java gateway process exited before sending its port number
[2025-02-01T20:14:33.534+0000] {taskinstance.py:1350} INFO - Marking task as FAILED. dag_id=ingestion_pipeline, task_id=generate_ingestion_data, execution_date=20250131T000000, start_date=20250201T201433, end_date=20250201T201433
[2025-02-01T20:14:33.544+0000] {standard_task_runner.py:109} ERROR - Failed to execute job 4 for task generate_ingestion_data (Java gateway process exited before sending its port number; 468)
[2025-02-01T20:14:33.554+0000] {local_task_job_runner.py:225} INFO - Task exited with return code 1
[2025-02-01T20:14:33.573+0000] {taskinstance.py:2653} INFO - 0 downstream tasks scheduled from follow-on schedule check
[2025-02-01T20:54:18.797+0000] {taskinstance.py:1103} INFO - Dependencies all met for dep_context=non-requeueable deps ti=<TaskInstance: ingestion_pipeline.generate_ingestion_data scheduled__2025-01-31T00:00:00+00:00 [queued]>
[2025-02-01T20:54:18.804+0000] {taskinstance.py:1103} INFO - Dependencies all met for dep_context=requeueable deps ti=<TaskInstance: ingestion_pipeline.generate_ingestion_data scheduled__2025-01-31T00:00:00+00:00 [queued]>
[2025-02-01T20:54:18.804+0000] {taskinstance.py:1308} INFO - Starting attempt 1 of 1
[2025-02-01T20:54:18.814+0000] {taskinstance.py:1327} INFO - Executing <Task(PythonOperator): generate_ingestion_data> on 2025-01-31 00:00:00+00:00
[2025-02-01T20:54:18.817+0000] {standard_task_runner.py:57} INFO - Started process 356 to run task
[2025-02-01T20:54:18.821+0000] {standard_task_runner.py:84} INFO - Running: ['***', 'tasks', 'run', 'ingestion_pipeline', 'generate_ingestion_data', 'scheduled__2025-01-31T00:00:00+00:00', '--job-id', '3', '--raw', '--subdir', 'DAGS_FOLDER/upstreams_data_ingestion_pipeline.py', '--cfg-path', '/tmp/tmp9uku2chg']
[2025-02-01T20:54:18.823+0000] {standard_task_runner.py:85} INFO - Job 3: Subtask generate_ingestion_data
[2025-02-01T20:54:18.864+0000] {task_command.py:410} INFO - Running <TaskInstance: ingestion_pipeline.generate_ingestion_data scheduled__2025-01-31T00:00:00+00:00 [running]> on host 33a4fec4b151
[2025-02-01T20:54:18.917+0000] {taskinstance.py:1547} INFO - Exporting env vars: AIRFLOW_CTX_DAG_OWNER='***' AIRFLOW_CTX_DAG_ID='ingestion_pipeline' AIRFLOW_CTX_TASK_ID='generate_ingestion_data' AIRFLOW_CTX_EXECUTION_DATE='2025-01-31T00:00:00+00:00' AIRFLOW_CTX_TRY_NUMBER='1' AIRFLOW_CTX_DAG_RUN_ID='scheduled__2025-01-31T00:00:00+00:00'
[2025-02-01T20:54:19.035+0000] {taskinstance.py:1824} ERROR - Task failed with exception
Traceback (most recent call last):
  File "/home/airflow/.local/lib/python3.7/site-packages/airflow/operators/python.py", line 181, in execute
    return_value = self.execute_callable()
  File "/home/airflow/.local/lib/python3.7/site-packages/airflow/operators/python.py", line 198, in execute_callable
    return self.python_callable(*self.op_args, **self.op_kwargs)
  File "/opt/airflow/dags/upstreams_curation.py", line 26, in generate_ingestion_data
    .config("spark.executorEnv.JAVA_HOME", os.environ['JAVA_HOME']) \
  File "/home/airflow/.local/lib/python3.7/site-packages/pyspark/sql/session.py", line 269, in getOrCreate
    sc = SparkContext.getOrCreate(sparkConf)
  File "/home/airflow/.local/lib/python3.7/site-packages/pyspark/context.py", line 483, in getOrCreate
    SparkContext(conf=conf or SparkConf())
  File "/home/airflow/.local/lib/python3.7/site-packages/pyspark/context.py", line 195, in __init__
    SparkContext._ensure_initialized(self, gateway=gateway, conf=conf)
  File "/home/airflow/.local/lib/python3.7/site-packages/pyspark/context.py", line 417, in _ensure_initialized
    SparkContext._gateway = gateway or launch_gateway(conf)
  File "/home/airflow/.local/lib/python3.7/site-packages/pyspark/java_gateway.py", line 106, in launch_gateway
    raise RuntimeError("Java gateway process exited before sending its port number")
RuntimeError: Java gateway process exited before sending its port number
[2025-02-01T20:54:19.045+0000] {taskinstance.py:1350} INFO - Marking task as FAILED. dag_id=ingestion_pipeline, task_id=generate_ingestion_data, execution_date=20250131T000000, start_date=20250201T205418, end_date=20250201T205419
[2025-02-01T20:54:19.055+0000] {standard_task_runner.py:109} ERROR - Failed to execute job 3 for task generate_ingestion_data (Java gateway process exited before sending its port number; 356)
[2025-02-01T20:54:19.080+0000] {local_task_job_runner.py:225} INFO - Task exited with return code 1
[2025-02-01T20:54:19.098+0000] {taskinstance.py:2653} INFO - 0 downstream tasks scheduled from follow-on schedule check
[2025-02-01T23:46:52.501+0000] {taskinstance.py:1103} INFO - Dependencies all met for dep_context=non-requeueable deps ti=<TaskInstance: ingestion_pipeline.generate_ingestion_data scheduled__2025-01-31T00:00:00+00:00 [queued]>
[2025-02-01T23:46:52.509+0000] {taskinstance.py:1103} INFO - Dependencies all met for dep_context=requeueable deps ti=<TaskInstance: ingestion_pipeline.generate_ingestion_data scheduled__2025-01-31T00:00:00+00:00 [queued]>
[2025-02-01T23:46:52.509+0000] {taskinstance.py:1308} INFO - Starting attempt 1 of 1
[2025-02-01T23:46:52.518+0000] {taskinstance.py:1327} INFO - Executing <Task(SparkSubmitOperator): generate_ingestion_data> on 2025-01-31 00:00:00+00:00
[2025-02-01T23:46:52.521+0000] {standard_task_runner.py:57} INFO - Started process 641 to run task
[2025-02-01T23:46:52.524+0000] {standard_task_runner.py:84} INFO - Running: ['***', 'tasks', 'run', 'ingestion_pipeline', 'generate_ingestion_data', 'scheduled__2025-01-31T00:00:00+00:00', '--job-id', '4', '--raw', '--subdir', 'DAGS_FOLDER/upstreams_data_ingestion_pipeline.py', '--cfg-path', '/tmp/tmpov4g2qbk']
[2025-02-01T23:46:52.526+0000] {standard_task_runner.py:85} INFO - Job 4: Subtask generate_ingestion_data
[2025-02-01T23:46:52.566+0000] {task_command.py:410} INFO - Running <TaskInstance: ingestion_pipeline.generate_ingestion_data scheduled__2025-01-31T00:00:00+00:00 [running]> on host 419fb3cffe45
[2025-02-01T23:46:52.630+0000] {taskinstance.py:1547} INFO - Exporting env vars: AIRFLOW_CTX_DAG_OWNER='***' AIRFLOW_CTX_DAG_ID='ingestion_pipeline' AIRFLOW_CTX_TASK_ID='generate_ingestion_data' AIRFLOW_CTX_EXECUTION_DATE='2025-01-31T00:00:00+00:00' AIRFLOW_CTX_TRY_NUMBER='1' AIRFLOW_CTX_DAG_RUN_ID='scheduled__2025-01-31T00:00:00+00:00'
[2025-02-01T23:46:52.637+0000] {base.py:73} INFO - Using connection ID 'spark_default' for task execution.
[2025-02-01T23:46:52.638+0000] {spark_submit.py:339} INFO - Spark-Submit cmd: spark-submit --master yarn --conf spark.executor.instances=4 --conf spark.executor.memory=4g --conf spark.driver.memory=2g --conf spark.sql.shuffle.partitions=8 --conf spark.yarn.appMasterEnv.JAVA_HOME=/usr/lib/jvm/java-11-openjdk-amd64 --name arrow-spark --verbose --queue root.default /opt/***/src/ingestion_app.py
[2025-02-01T23:46:52.664+0000] {spark_submit.py:490} INFO - /opt/spark/bin/spark-class: line 71: /usr/lib/jvm/java-11-openjdk-amd64/bin/java: No such file or directory
[2025-02-01T23:46:52.665+0000] {spark_submit.py:490} INFO - /opt/spark/bin/spark-class: line 97: CMD: bad array subscript
[2025-02-01T23:46:52.679+0000] {taskinstance.py:1824} ERROR - Task failed with exception
Traceback (most recent call last):
  File "/home/airflow/.local/lib/python3.7/site-packages/airflow/providers/apache/spark/operators/spark_submit.py", line 157, in execute
    self._hook.submit(self._application)
  File "/home/airflow/.local/lib/python3.7/site-packages/airflow/providers/apache/spark/hooks/spark_submit.py", line 422, in submit
    f"Cannot execute: {self._mask_cmd(spark_submit_cmd)}. Error code is: {returncode}."
airflow.exceptions.AirflowException: Cannot execute: spark-submit --master yarn --conf spark.executor.instances=4 --conf spark.executor.memory=4g --conf spark.driver.memory=2g --conf spark.sql.shuffle.partitions=8 --conf spark.yarn.appMasterEnv.JAVA_HOME=/usr/lib/jvm/java-11-openjdk-amd64 --name arrow-spark --verbose --queue root.default /opt/***/src/ingestion_app.py. Error code is: 1.
[2025-02-01T23:46:52.682+0000] {taskinstance.py:1350} INFO - Marking task as FAILED. dag_id=ingestion_pipeline, task_id=generate_ingestion_data, execution_date=20250131T000000, start_date=20250201T234652, end_date=20250201T234652
[2025-02-01T23:46:52.692+0000] {standard_task_runner.py:109} ERROR - Failed to execute job 4 for task generate_ingestion_data (Cannot execute: spark-submit --master yarn --conf spark.executor.instances=4 --conf spark.executor.memory=4g --conf spark.driver.memory=2g --conf spark.sql.shuffle.partitions=8 --conf spark.yarn.appMasterEnv.JAVA_HOME=/usr/lib/jvm/java-11-openjdk-amd64 --name arrow-spark --verbose --queue root.default /opt/***/src/ingestion_app.py. Error code is: 1.; 641)
[2025-02-01T23:46:52.712+0000] {local_task_job_runner.py:225} INFO - Task exited with return code 1
[2025-02-01T23:46:52.729+0000] {taskinstance.py:2653} INFO - 0 downstream tasks scheduled from follow-on schedule check
