[2025-03-01T16:50:03.327+0000] {taskinstance.py:1103} INFO - Dependencies all met for dep_context=non-requeueable deps ti=<TaskInstance: ingestion_pipeline.data_ingestion scheduled__2025-03-01T16:48:00+00:00 [queued]>
[2025-03-01T16:50:03.334+0000] {taskinstance.py:1103} INFO - Dependencies all met for dep_context=requeueable deps ti=<TaskInstance: ingestion_pipeline.data_ingestion scheduled__2025-03-01T16:48:00+00:00 [queued]>
[2025-03-01T16:50:03.334+0000] {taskinstance.py:1308} INFO - Starting attempt 1 of 1
[2025-03-01T16:50:03.346+0000] {taskinstance.py:1327} INFO - Executing <Task(PythonOperator): data_ingestion> on 2025-03-01 16:48:00+00:00
[2025-03-01T16:50:03.353+0000] {standard_task_runner.py:57} INFO - Started process 3630 to run task
[2025-03-01T16:50:03.359+0000] {standard_task_runner.py:84} INFO - Running: ['***', 'tasks', 'run', 'ingestion_pipeline', 'data_ingestion', 'scheduled__2025-03-01T16:48:00+00:00', '--job-id', '226', '--raw', '--subdir', 'DAGS_FOLDER/ingestion_pipeline.py', '--cfg-path', '/tmp/tmp8p4pwrzc']
[2025-03-01T16:50:03.365+0000] {standard_task_runner.py:85} INFO - Job 226: Subtask data_ingestion
[2025-03-01T16:50:03.418+0000] {task_command.py:410} INFO - Running <TaskInstance: ingestion_pipeline.data_ingestion scheduled__2025-03-01T16:48:00+00:00 [running]> on host dbd9e82b6084
[2025-03-01T16:50:03.499+0000] {taskinstance.py:1547} INFO - Exporting env vars: AIRFLOW_CTX_DAG_OWNER='***' AIRFLOW_CTX_DAG_ID='ingestion_pipeline' AIRFLOW_CTX_TASK_ID='data_ingestion' AIRFLOW_CTX_EXECUTION_DATE='2025-03-01T16:48:00+00:00' AIRFLOW_CTX_TRY_NUMBER='1' AIRFLOW_CTX_DAG_RUN_ID='scheduled__2025-03-01T16:48:00+00:00'
[2025-03-01T16:50:03.501+0000] {taskinstance.py:1824} ERROR - Task failed with exception
Traceback (most recent call last):
  File "/home/airflow/.local/lib/python3.7/site-packages/airflow/operators/python.py", line 181, in execute
    return_value = self.execute_callable()
  File "/home/airflow/.local/lib/python3.7/site-packages/airflow/operators/python.py", line 198, in execute_callable
    return self.python_callable(*self.op_args, **self.op_kwargs)
  File "/opt/airflow/dags/upstreams_curation.py", line 20, in generate_ingestion_data
    os.makedirs(ingestion_dir, exist_ok=True)
  File "/usr/local/lib/python3.7/os.py", line 223, in makedirs
    mkdir(name, mode)
FileNotFoundError: [Errno 2] No such file or directory: 'data/ingestion'
[2025-03-01T16:50:03.509+0000] {taskinstance.py:1350} INFO - Marking task as FAILED. dag_id=ingestion_pipeline, task_id=data_ingestion, execution_date=20250301T164800, start_date=20250301T165003, end_date=20250301T165003
[2025-03-01T16:50:03.516+0000] {standard_task_runner.py:109} ERROR - Failed to execute job 226 for task data_ingestion ([Errno 2] No such file or directory: 'data/ingestion'; 3630)
[2025-03-01T16:50:03.534+0000] {local_task_job_runner.py:225} INFO - Task exited with return code 1
[2025-03-01T16:50:03.558+0000] {taskinstance.py:2653} INFO - 0 downstream tasks scheduled from follow-on schedule check
