[2025-02-02T00:16:42.280+0000] {taskinstance.py:1103} INFO - Dependencies all met for dep_context=non-requeueable deps ti=<TaskInstance: data_quality_pipeline.validate_data scheduled__2025-02-01T00:00:00+00:00 [queued]>
[2025-02-02T00:16:42.288+0000] {taskinstance.py:1103} INFO - Dependencies all met for dep_context=requeueable deps ti=<TaskInstance: data_quality_pipeline.validate_data scheduled__2025-02-01T00:00:00+00:00 [queued]>
[2025-02-02T00:16:42.288+0000] {taskinstance.py:1308} INFO - Starting attempt 1 of 1
[2025-02-02T00:16:42.298+0000] {taskinstance.py:1327} INFO - Executing <Task(PythonOperator): validate_data> on 2025-02-01 00:00:00+00:00
[2025-02-02T00:16:42.302+0000] {standard_task_runner.py:57} INFO - Started process 767 to run task
[2025-02-02T00:16:42.305+0000] {standard_task_runner.py:84} INFO - Running: ['***', 'tasks', 'run', 'data_quality_pipeline', 'validate_data', 'scheduled__2025-02-01T00:00:00+00:00', '--job-id', '22', '--raw', '--subdir', 'DAGS_FOLDER/data_quality_pipeline.py', '--cfg-path', '/tmp/tmpxy6c5pr0']
[2025-02-02T00:16:42.308+0000] {standard_task_runner.py:85} INFO - Job 22: Subtask validate_data
[2025-02-02T00:16:42.348+0000] {task_command.py:410} INFO - Running <TaskInstance: data_quality_pipeline.validate_data scheduled__2025-02-01T00:00:00+00:00 [running]> on host 41901dcf10be
[2025-02-02T00:16:42.406+0000] {taskinstance.py:1547} INFO - Exporting env vars: AIRFLOW_CTX_DAG_OWNER='***' AIRFLOW_CTX_DAG_ID='data_quality_pipeline' AIRFLOW_CTX_TASK_ID='validate_data' AIRFLOW_CTX_EXECUTION_DATE='2025-02-01T00:00:00+00:00' AIRFLOW_CTX_TRY_NUMBER='1' AIRFLOW_CTX_DAG_RUN_ID='scheduled__2025-02-01T00:00:00+00:00'
[2025-02-02T00:16:42.525+0000] {taskinstance.py:1824} ERROR - Task failed with exception
Traceback (most recent call last):
  File "/home/airflow/.local/lib/python3.7/site-packages/airflow/operators/python.py", line 181, in execute
    return_value = self.execute_callable()
  File "/home/airflow/.local/lib/python3.7/site-packages/airflow/operators/python.py", line 198, in execute_callable
    return self.python_callable(*self.op_args, **self.op_kwargs)
  File "/opt/airflow/dags/data_quality.py", line 20, in validate_data
    .config("spark.sql.shuffle.partitions", "4") \
  File "/home/airflow/.local/lib/python3.7/site-packages/pyspark/sql/session.py", line 269, in getOrCreate
    sc = SparkContext.getOrCreate(sparkConf)
  File "/home/airflow/.local/lib/python3.7/site-packages/pyspark/context.py", line 483, in getOrCreate
    SparkContext(conf=conf or SparkConf())
  File "/home/airflow/.local/lib/python3.7/site-packages/pyspark/context.py", line 195, in __init__
    SparkContext._ensure_initialized(self, gateway=gateway, conf=conf)
  File "/home/airflow/.local/lib/python3.7/site-packages/pyspark/context.py", line 417, in _ensure_initialized
    SparkContext._gateway = gateway or launch_gateway(conf)
  File "/home/airflow/.local/lib/python3.7/site-packages/pyspark/java_gateway.py", line 106, in launch_gateway
    raise RuntimeError("Java gateway process exited before sending its port number")
RuntimeError: Java gateway process exited before sending its port number
[2025-02-02T00:16:42.537+0000] {taskinstance.py:1350} INFO - Marking task as FAILED. dag_id=data_quality_pipeline, task_id=validate_data, execution_date=20250201T000000, start_date=20250202T001642, end_date=20250202T001642
[2025-02-02T00:16:42.550+0000] {standard_task_runner.py:109} ERROR - Failed to execute job 22 for task validate_data (Java gateway process exited before sending its port number; 767)
[2025-02-02T00:16:42.564+0000] {local_task_job_runner.py:225} INFO - Task exited with return code 1
[2025-02-02T00:16:42.586+0000] {taskinstance.py:2653} INFO - 0 downstream tasks scheduled from follow-on schedule check
