[2025-02-22T00:10:09.659+0000] {taskinstance.py:1103} INFO - Dependencies all met for dep_context=non-requeueable deps ti=<TaskInstance: indexing_pipeline.index_data scheduled__2025-02-21T00:00:00+00:00 [queued]>
[2025-02-22T00:10:09.666+0000] {taskinstance.py:1103} INFO - Dependencies all met for dep_context=requeueable deps ti=<TaskInstance: indexing_pipeline.index_data scheduled__2025-02-21T00:00:00+00:00 [queued]>
[2025-02-22T00:10:09.666+0000] {taskinstance.py:1308} INFO - Starting attempt 1 of 1
[2025-02-22T00:10:09.675+0000] {taskinstance.py:1327} INFO - Executing <Task(PythonOperator): index_data> on 2025-02-21 00:00:00+00:00
[2025-02-22T00:10:09.680+0000] {standard_task_runner.py:57} INFO - Started process 5733 to run task
[2025-02-22T00:10:09.683+0000] {standard_task_runner.py:84} INFO - Running: ['***', 'tasks', 'run', 'indexing_pipeline', 'index_data', 'scheduled__2025-02-21T00:00:00+00:00', '--job-id', '131', '--raw', '--subdir', 'DAGS_FOLDER/indexing_pipeline.py', '--cfg-path', '/tmp/tmp8eidcl2z']
[2025-02-22T00:10:09.685+0000] {standard_task_runner.py:85} INFO - Job 131: Subtask index_data
[2025-02-22T00:10:09.718+0000] {task_command.py:410} INFO - Running <TaskInstance: indexing_pipeline.index_data scheduled__2025-02-21T00:00:00+00:00 [running]> on host 29612c003465
[2025-02-22T00:10:09.772+0000] {taskinstance.py:1547} INFO - Exporting env vars: AIRFLOW_CTX_DAG_OWNER='***' AIRFLOW_CTX_DAG_ID='indexing_pipeline' AIRFLOW_CTX_TASK_ID='index_data' AIRFLOW_CTX_EXECUTION_DATE='2025-02-21T00:00:00+00:00' AIRFLOW_CTX_TRY_NUMBER='1' AIRFLOW_CTX_DAG_RUN_ID='scheduled__2025-02-21T00:00:00+00:00'
[2025-02-22T00:10:09.889+0000] {taskinstance.py:1824} ERROR - Task failed with exception
Traceback (most recent call last):
  File "/home/airflow/.local/lib/python3.7/site-packages/airflow/operators/python.py", line 181, in execute
    return_value = self.execute_callable()
  File "/home/airflow/.local/lib/python3.7/site-packages/airflow/operators/python.py", line 198, in execute_callable
    return self.python_callable(*self.op_args, **self.op_kwargs)
  File "/opt/airflow/dags/indexing.py", line 38, in index_data
    .config("spark.sql.shuffle.partitions", "8") \
  File "/home/airflow/.local/lib/python3.7/site-packages/pyspark/sql/session.py", line 269, in getOrCreate
    sc = SparkContext.getOrCreate(sparkConf)
  File "/home/airflow/.local/lib/python3.7/site-packages/pyspark/context.py", line 483, in getOrCreate
    SparkContext(conf=conf or SparkConf())
  File "/home/airflow/.local/lib/python3.7/site-packages/pyspark/context.py", line 195, in __init__
    SparkContext._ensure_initialized(self, gateway=gateway, conf=conf)
  File "/home/airflow/.local/lib/python3.7/site-packages/pyspark/context.py", line 417, in _ensure_initialized
    SparkContext._gateway = gateway or launch_gateway(conf)
  File "/home/airflow/.local/lib/python3.7/site-packages/pyspark/java_gateway.py", line 106, in launch_gateway
    raise RuntimeError("Java gateway process exited before sending its port number")
RuntimeError: Java gateway process exited before sending its port number
[2025-02-22T00:10:09.898+0000] {taskinstance.py:1350} INFO - Marking task as FAILED. dag_id=indexing_pipeline, task_id=index_data, execution_date=20250221T000000, start_date=20250222T001009, end_date=20250222T001009
[2025-02-22T00:10:09.908+0000] {standard_task_runner.py:109} ERROR - Failed to execute job 131 for task index_data (Java gateway process exited before sending its port number; 5733)
[2025-02-22T00:10:09.946+0000] {local_task_job_runner.py:225} INFO - Task exited with return code 1
[2025-02-22T00:10:09.966+0000] {taskinstance.py:2653} INFO - 0 downstream tasks scheduled from follow-on schedule check
